Workbook

Sheet Input Data
A1: KODE | B1: TANGGAL | C1: NAMA | D1: WHATSAPP | E1: SOURCE | F1: AGEN | G1: STATUS | H1: PAKET / DESTINASI | I1: TANGGAL TRIP | J1: PAX | K1: ESTIMASI NILAI ORDER | L1: KETERANGAN | M1: TAHAPAN (STATUS) | N1: ANALISA AI
A2: 2601A001 | B2: 46023 | C2: Cynthia | D2: 081249880600 | E2: Website | F2: Alvin | G2: Closing | H2: Menjangan Tabuhan | I2: 46025 | J2: 10+1 | K2: 7905000 | L2: tambah foto video | M2: {=IF( G2:G5505="", "", IFERROR( IFS( G2:G5505="Leads Baru",1, G2:G5505="Qualified",2, G2:G5505="Prospek",3, G2:G5505="Follow Up",4, G2:G5505="Warm Leads",5, G2:G5505="Hot Leads",6, G2:G5505="Closing",7, G2:G5505="Gagal",8 ), 99 ) )} -> 7
A3: 2601A002 | B3: 46023 | C3: Dewitri | D3: 085776495791 | E3: Website | F3: Alvin | G3: Gagal | H3: Kawah ijen | I3: 46023 | J3: 3 | M3: 8
A4: 2601A003 | B4: 46024 | C4: Ulil albab | D4: 08561542812 | E4: Website | F4: Alvin | G4: Gagal | H4: Trip MT | I4: 46024 | J4: 4 | L4: Over budget | M4: 8
A5: 2601A004 | B5: 46024 | C5: Anto | D5: 0818950503 | E5: Website | F5: Alvin | G5: Gagal | L5: jadinya ke malang | M5: 8
A6: 2601A005 | B6: 46026 | C6: Tjen bie | D6: 081330627337 | E6: Website | F6: Alvin | G6: Gagal | H6: 3H2M Z | I6: 46027 | J6: 2 | L6: Jadi ke lovina | M6: 8
A7: 2601A006 | B7: 46027 | C7: Anindita purnamasari | D7: 082233330301 | E7: Website | F7: Alvin | G7: Gagal | H7: 2H1M | J7: 2 | L7: dikabari jika jadi ambil paketnya | M7: 8
A8: 2601A007 | B8: 46027 | C8: Riska | D8: 08994700800 | E8: Website | F8: Alvin | G8: Gagal | H8: 3H2M A | J8: 10 | L8: tanya tanya, masih blm jawab follow up | M8: 8
A9: 2601A008 | B9: 46029 | C9: Helmi | D9: 083826179860‬ | E9: Website | F9: Alvin | G9: Gagal | H9: 1D IB | I9: 46030 | J9: 3 | K9: 2076000 | L9: order | M9: 8
A10: 2601A009 | B10: 46030 | C10: Ruly | D10: 08170934898 | E10: Website | F10: Alvin | G10: Gagal | H10: 3H2M A | J10: 2 | L10: Tidak jawab | M10: 8
A11: 2601A010 | B11: 46030 | C11: Stephan | D11: 085105912829 | E11: Website | F11: Alvin | G11: Gagal | H11: 4H3M | I11: akhir januari | J11: 2 | L11: lagi pikir-pikir, FU pertengahan januari | M11: 8
A12: 2601A011 | B12: 46031 | C12: carone | D12: 0877933043674 | E12: Lainnya | F12: Alvin | G12: Gagal | H12: 3H2M | L12: Masih tanya tanya | M12: 8
A13: 2601D001 | B13: 46023 | C13: H | D13: 082114698226 | E13: Instagram | F13: Dela | G13: Gagal | H13: 2H1M | I13: 16-18 januari | L13: Nanti dikabari | M13: 8
A14: 2601A012 | B14: 46031 | C14: Giet | D14: 085377504433 | E14: Website | F14: Alvin | G14: Gagal | H14: 3H2M | L14: masih tanya tanya | M14: 8
A15: 2601D002 | B15: 46023 | C15: Ari.Januari.2026 | D15: 0881036053274 | E15: Website | F15: Dela | G15: Gagal | H15: CT | L15: ingin paket campervan | M15: 8
A16: 2601A013 | B16: 46032 | C16: Deni Sultan | D16: 081912435459‬ | E16: Website | F16: Alvin | G16: Closing | H16: MT | I16: 46046 | J16: 2 | K16: 590000 | L16: order | M16: 7
A17: 2601D003 | B17: 46023 | C17: Muliono | D17: 085851219044 | E17: Website | F17: Dela | G17: Gagal | H17: Trip baluran | J17: 7 | L17: Tidak jawab | M17: 8
A18: 2601D004 | B18: 46023 | C18: Berliana | D18: 085806069951 | E18: Instagram | F18: Dela | G18: Gagal | H18: one day trip | L18: Tidak jawab | M18: 8
A19: 2601D005 | B19: 46023 | C19: Muhammad Amrullah a.k | D19: 081393712742 | E19: Instagram | F19: Dela | G19: Gagal | H19: custom 3H2M | I19: Maret Akhir atau April | J19: 7 | K19: =1603393*7 -> 11223751 | L19: tidak ada jawaban | M19: 8
A20: 2601D006 | B20: 46023 | C20: Prima Gita | D20: 081284286428 | E20: Instagram | F20: Dela | G20: Gagal | H20: 2H1M opsi a | I20: menentukan waktu | L20: Tidak jawab | M20: 8
A21: 2601D007 | B21: 46023 | C21: Mia Bella | D21: 08133977533 | E21: Instagram | F21: Dela | G21: Gagal | H21: Ijen Baluran one day trip | I21: 46026 | J21: 2 | L21: 1 wni 1 wna, tdk jawab | M21: 8
A22: 2601D008 | B22: 46023 | C22: Kai | D22: 081399930501 | E22: Instagram | F22: Dela | G22: Gagal | H22: ot 3h2m | I22: 9-11 Januari 26 | L22: lewat tanggal | M22: 8
A23: 2601D009 | B23: 46024 | C23: Iin Noor Chozin | D23: 081233197590 | E23: Website | F23: Dela | G23: Closing | H23: Trip Menjangan Tabuhan | I23: 46025 | J23: 6 | K23: =410000*6 -> 2460000 | L23: menjangan tabuhan | M23: 7
A24: 2601D010 | B24: 46024 | C24: Dia Pur's | D24: 082360390604 | E24: Instagram | F24: Dela | G24: Gagal | H24: custom 2h1m | I24: 3 4 februari | J24: 4 | L24: tanggal lewat | M24: 8
A25: 2601D011 | B25: 46024 | C25: Inggrid | D25: 085156507128 | E25: Instagram | F25: Dela | G25: Gagal | H25: OT Januari | I25: Januari | L25: tidak jawab | M25: 8
A26: 2601D012 | B26: 46024 | C26: Kartika | D26: 082143617625 | E26: Website | F26: Dela | G26: Closing | H26: OT Menjangan Tabuhan | I26: 46033 | J26: 4 | K26: =295000*4 -> 1180000 | M26: 7
A27: 2601D013 | B27: 46024 | C27: Diyatrana | D27: 085729990708 | E27: Instagram | F27: Dela | G27: Gagal | H27: 3H2M opsi A | L27: tidak jawab | M27: 8
A28: 2601D014 | B28: 46024 | C28: Peni | D28: 081553992808 | E28: Instagram | F28: Dela | G28: Gagal | H28: Trip Pulau Bedil | I28: 46104 | J28: 4 | K28: =640000+192000*4 -> 1408000 | L28: pindah haluan liburan | M28: 8
A29: 2601D015 | B29: 46024 | C29: Kirana | D29: 085777785090 | E29: Website | F29: Dela | G29: Review | H29: custom 2h1m | I29: 6 -7 Februari | J29: 40 | K29: =2051220*20 -> 41024400 | L29: MINTA PAKET, fu akhir januari | M29: 99
A30: 2601D016 | B30: 46024 | C30: Ika W/ Ibu ms Nasir | D30: 0882007680200 | E30: Website | F30: Dela | G30: Gagal | H30: 2H1M opsi C | I30: 46170 | J30: 17 | L30: ganti ke bromo | M30: 8
A31: 2601D017 | B31: 46024 | C31: Karen | D31: 087772484641 | E31: Instagram | F31: Dela | G31: Gagal | H31: 2 paket open trip | I31: 4 dan 5 Maret 226 | J31: 2 | K31: =525000*2 -> 1050000 | L31: follow up tanggal 15 februari | M31: 8
A32: 2601D018 | B32: 46024 | C32: Tiyas | D32: 082136195477 | E32: Lainnya | F32: Dela | G32: Gagal | H32: Custom 2h1m | I32: 16 17 Januari 2026 | J32: 2 | L32: Minta Paket, fu tgl 10 | M32: 8
A33: 2601D019 | B33: 46025 | C33: Beta Amrina | D33: 082327577538 | E33: Instagram | F33: Dela | G33: Gagal | H33: OT | I33: Mei 14-16 2026 | J33: 3 | K33: =1600000*3 -> 4800000 | L33: tidak jawab | M33: 8
A34: 2601D020 | B34: 46025 | C34: Wa | D34: 085641568779 | E34: Lainnya | F34: Dela | G34: Gagal | H34: ot djawatan baluran | L34: tidak jawab | M34: 8
A35: 2601D021 | B35: 46025 | C35: Buds | D35: 085720585703 | E35: Website | F35: Dela | G35: Gagal | H35: Baluran private | L35: tidak jawab | M35: 8
A36: 2601D022 | B36: 46025 | C36: Seysa | D36: 085886980015 | E36: Instagram | F36: Dela | G36: Gagal | H36: trip kawah wurung | I36: 46028 | J36: 3 | L36: masih pikir2 dulu, sudah lewat tgl | M36: 8
A37: 2601D023 | B37: 46025 | C37: Nothing | D37: 085820515179 | E37: Website | F37: Dela | G37: Gagal | H37: Trip Kawah Ijen | L37: mepo sby atau gresik | M37: 8
A38: 2601D024 | B38: 46025 | C38: Dhevy Hariady | D38: 082282391601 | E38: Instagram | F38: Dela | G38: Gagal | H38: trip djawatan baluran | I38: Bulan Juni | J38: 4 | K38: =499000*4 -> 1996000 | L38: tidak jadi liburan ke BWI | M38: 8 | N38: https://docs.google.com/document/d/1wA6Vstebr_OPv-YiZuHCtRJ0dphAaw92AabZKFpW9i0/edit?tab=t.0
A39: 2601D025 | B39: 46025 | C39: Ratu (Bunda FazZZam) | D39: 081806567775 | E39: Instagram | F39: Dela | G39: Gagal | H39: OT 3H2M | L39: masih ngomong ke atasan | M39: 8
A40: 2601D026 | B40: 46025 | C40: Gilang | D40: 081221614470 | E40: Website | F40: Dela | G40: Closing | H40: Private Trip Kawah Wurung | I40: 46026 | J40: 1 | K40: 2318100 | M40: 7
...

Sheet Tahapan Leads
B3: Nomer | C3: Tahapan | D3: Keterangan | E3: Next Action | F3: Yes | G3: No
B4: 1 | C4: Leads Baru | D4: Menyapa dan tanya informasi | E4: Mengulik kebutuhan | F4: Masuk tahap 2 | G4: Follow up ringan (H+1), jika tidak respon → arsip sementara, lebih dari seminggu jadi gagal
B5: 2 | C5: Qualified | D5: Menyampaikan kebutuhan | E5: Kirim penawaran | F5: Masuk tahap 3 | G5: Edukasi ulang / klarifikasi kebutuhan (jangan kirim promo)
B6: 3 | C6: Prospek | D6: Sudah tertarik tapi belum komitmen | E6: Edukasi, beri kepercayaan, kirim voice note, tawari telfon | F6: Masuk tahap 4 | G6: Jadwalkan follow up (H+2 / H+3)
B7: 4 | C7: Follow Up | D7: Sudah dikasih edukasi tapi belum komitmen | E7: Menanyakan atau membuat janji waktu follow up | F7: Masuk tahap 5 | G7: Pindahkan ke Warm Leads (cooling)
B8: 5 | C8: Warm Leads | D8: Sudah difollowup tapi belum komitmen juga | E8: Kasih urgency slot atau bonus atau promo | F8: Masuk tahap 6 | G8: Pending / Dormant (tunggu momen, jangan kejar terus)
B9: 6 | C9: Hot Leads | D9: Terima form reservasi / terima invoice | E9: Menanyakan DP | F9: Masuk tahap 7 | G9: Follow up deadline DP (H+1), jika gagal → balik ke Warm
B10: 7 | C10: Closing | D10: Sudah reservasi | E10: Input data reservasi, kirim form reservasi ke grup, kirim itinerary & RAB ke Business Operation
B11: 8 | C11: Review | D11: Meminta review ke tamu setelah trip selesai | E11: Laporan ke Business Operation
B14: 1 | C14: Meminta itinerary dan RAB ke sales
B15: 2 | C15: Koordinasi dengan sales vendor mana aja yang sudah dipesan dan belum dipesan
B16: 3 | C16: Membuat list vendor yang belum dipesan sama sales
B17: 4 | C17: Memesan vendor yang belum dipesan sama sales
B18: 5 | C18: Update data reservasi ketika sudah ready
B19: 6 | C19: Memastikan ulang semua ready di H-3 trip
B20: 7 | C20: Monitoring saat trip berjalan
B21: 8 | C21: Follow up ke crew untuk meminta sumber leads tamu dan kirim link review
B22: 9 | C22: Ketika trip selesai, menanyakan laporan trip ke crew yang bertugas
B23: 10 | C23: Kirim nomer PIC ke crew yang bertugas untuk laporan operasional trip
B24: 11 | C24: Meminta review ke tamu jika tamu belum review di google business H+3

Sheet Leads_Dela
A1: =IFERROR(__xludf.DUMMYFUNCTION("QUERY( 'Input Data'!A1:N5505, ""select B, A, C, D, E, G, H, I, J, K, L, N where F = 'Dela'"", 1 ) "),"TANGGAL") -> TANGGAL | B1: =IFERROR(__xludf.DUMMYFUNCTION("""COMPUTED_VALUE"""),"KODE") -> KODE | C1: =IFERROR(__xludf.DUMMYFUNCTION("""COMPUTED_VALUE"""),"NAMA") -> NAMA | D1: =IFERROR(__xludf.DUMMYFUNCTION("""COMPUTED_VALUE"""),"WHATSAPP") -> WHATSAPP | E1: =IFERROR(__xludf.DUMMYFUNCTION("""COMPUTED_VALUE"""),"SOURCE") -> SOURCE | F1: =IFERROR(__xludf.DUMMYFUNCTION("""COMPUTED_VALUE"""),"STATUS") -> STATUS | G1: =IFERROR(__xludf.DUMMYFUNCTION("""COMPUTED_VALUE"""),"PAKET / DESTINASI") -> PAKET / DESTINASI | H1: =IFERROR(__xludf.DUMMYFUNCTION("""COMPUTED_VALUE"""),"TANGGAL TRIP") -> TANGGAL TRIP | I1: =IFERROR(__xludf.DUMMYFUNCTION("""COMPUTED_VALUE"""),"PAX") -> PAX | J1: =IFERROR(__xludf.DUMMYFUNCTION("""COMPUTED_VALUE"""),"ESTIMASI NILAI ORDER") -> ESTIMASI NILAI ORDER | K1: =IFERROR(__xludf.DUMMYFUNCTION("""COMPUTED_VALUE"""),"KETERANGAN") -> KETERANGAN | L1: =IFERROR(__xludf.DUMMYFUNCTION("""COMPUTED_VALUE"""),"ANALISA AI") -> ANALISA AI
A2: =IFERROR(__xludf.DUMMYFUNCTION("""COMPUTED_VALUE"""),46023.0) -> 46023 | B2: =IFERROR(__xludf.DUMMYFUNCTION("""COMPUTED_VALUE"""),"2601D001") -> 2601D001 | C2: =IFERROR(__xludf.DUMMYFUNCTION("""COMPUTED_VALUE"""),"H ") -> H | D2: =IFERROR(__xludf.DUMMYFUNCTION("""COMPUTED_VALUE"""),"082114698226") -> 082114698226 | E2: =IFERROR(__xludf.DUMMYFUNCTION("""COMPUTED_VALUE"""),"Instagram") -> Instagram | F2: =IFERROR(__xludf.DUMMYFUNCTION("""COMPUTED_VALUE"""),"Gagal") -> Gagal | G2: =IFERROR(__xludf.DUMMYFUNCTION("""COMPUTED_VALUE"""),"2H1M") -> 2H1M | K2: =IFERROR(__xludf.DUMMYFUNCTION("""COMPUTED_VALUE"""),"Nanti dikabari") -> Nanti dikabari
A3: =IFERROR(__xludf.DUMMYFUNCTION("""COMPUTED_VALUE"""),46023.0) -> 46023 | B3: =IFERROR(__xludf.DUMMYFUNCTION("""COMPUTED_VALUE"""),"2601D002") -> 2601D002 | C3: =IFERROR(__xludf.DUMMYFUNCTION("""COMPUTED_VALUE"""),"Ari.Januari.2026") -> Ari.Januari.2026 | D3: =IFERROR(__xludf.DUMMYFUNCTION("""COMPUTED_VALUE"""),"0881036053274") -> 0881036053274 | E3: =IFERROR(__xludf.DUMMYFUNCTION("""COMPUTED_VALUE"""),"Website") -> Website | F3: =IFERROR(__xludf.DUMMYFUNCTION("""COMPUTED_VALUE"""),"Gagal") -> Gagal | G3: =IFERROR(__xludf.DUMMYFUNCTION("""COMPUTED_VALUE"""),"CT") -> CT | K3: =IFERROR(__xludf.DUMMYFUNCTION("""COMPUTED_VALUE"""),"ingin paket campervan") -> ingin paket campervan
A4: =IFERROR(__xludf.DUMMYFUNCTION("""COMPUTED_VALUE"""),46023.0) -> 46023 | B4: =IFERROR(__xludf.DUMMYFUNCTION("""COMPUTED_VALUE"""),"2601D003") -> 2601D003 | C4: =IFERROR(__xludf.DUMMYFUNCTION("""COMPUTED_VALUE"""),"Muliono") -> Muliono | D4: =IFERROR(__xludf.DUMMYFUNCTION("""COMPUTED_VALUE"""),"085851219044") -> 085851219044 | E4: =IFERROR(__xludf.DUMMYFUNCTION("""COMPUTED_VALUE"""),"Website") -> Website | F4: =IFERROR(__xludf.DUMMYFUNCTION("""COMPUTED_VALUE"""),"Gagal") -> Gagal | G4: =IFERROR(__xludf.DUMMYFUNCTION("""COMPUTED_VALUE"""),"Trip baluran ") -> Trip baluran | I4: =IFERROR(__xludf.DUMMYFUNCTION("""COMPUTED_VALUE"""),7.0) -> 7 | K4: =IFERROR(__xludf.DUMMYFUNCTION("""COMPUTED_VALUE"""),"Tidak jawab") -> Tidak jawab
A5: =IFERROR(__xludf.DUMMYFUNCTION("""COMPUTED_VALUE"""),46023.0) -> 46023 | B5: =IFERROR(__xludf.DUMMYFUNCTION("""COMPUTED_VALUE"""),"2601D004") -> 2601D004 | C5: =IFERROR(__xludf.DUMMYFUNCTION("""COMPUTED_VALUE"""),"Berliana") -> Berliana | D5: =IFERROR(__xludf.DUMMYFUNCTION("""COMPUTED_VALUE"""),"085806069951") -> 085806069951 | E5: =IFERROR(__xludf.DUMMYFUNCTION("""COMPUTED_VALUE"""),"Instagram") -> Instagram | F5: =IFERROR(__xludf.DUMMYFUNCTION("""COMPUTED_VALUE"""),"Gagal") -> Gagal | G5: =IFERROR(__xludf.DUMMYFUNCTION("""COMPUTED_VALUE"""),"one day trip") -> one day trip | K5: =IFERROR(__xludf.DUMMYFUNCTION("""COMPUTED_VALUE"""),"Tidak jawab") -> Tidak jawab
A6: =IFERROR(__xludf.DUMMYFUNCTION("""COMPUTED_VALUE"""),46023.0) -> 46023 | B6: =IFERROR(__xludf.DUMMYFUNCTION("""COMPUTED_VALUE"""),"2601D005") -> 2601D005 | C6: =IFERROR(__xludf.DUMMYFUNCTION("""COMPUTED_VALUE"""),"Muhammad Amrullah a.k") -> Muhammad Amrullah a.k | D6: =IFERROR(__xludf.DUMMYFUNCTION("""COMPUTED_VALUE"""),"081393712742") -> 081393712742 | E6: =IFERROR(__xludf.DUMMYFUNCTION("""COMPUTED_VALUE"""),"Instagram") -> Instagram | F6: =IFERROR(__xludf.DUMMYFUNCTION("""COMPUTED_VALUE"""),"Gagal") -> Gagal | G6: =IFERROR(__xludf.DUMMYFUNCTION("""COMPUTED_VALUE"""),"custom 3H2M") -> custom 3H2M | I6: =IFERROR(__xludf.DUMMYFUNCTION("""COMPUTED_VALUE"""),7.0) -> 7 | J6: =IFERROR(__xludf.DUMMYFUNCTION("""COMPUTED_VALUE"""),1.1223751E7) -> 11223751 | K6: =IFERROR(__xludf.DUMMYFUNCTION("""COMPUTED_VALUE"""),"tidak ada jawaban") -> tidak ada jawaban
A7: =IFERROR(__xludf.DUMMYFUNCTION("""COMPUTED_VALUE"""),46023.0) -> 46023 | B7: =IFERROR(__xludf.DUMMYFUNCTION("""COMPUTED_VALUE"""),"2601D006") -> 2601D006 | C7: =IFERROR(__xludf.DUMMYFUNCTION("""COMPUTED_VALUE"""),"Prima Gita") -> Prima Gita | D7: =IFERROR(__xludf.DUMMYFUNCTION("""COMPUTED_VALUE"""),"081284286428") -> 081284286428 | E7: =IFERROR(__xludf.DUMMYFUNCTION("""COMPUTED_VALUE"""),"Instagram") -> Instagram | F7: =IFERROR(__xludf.DUMMYFUNCTION("""COMPUTED_VALUE"""),"Gagal") -> Gagal | G7: =IFERROR(__xludf.DUMMYFUNCTION("""COMPUTED_VALUE"""),"2H1M opsi a") -> 2H1M opsi a | K7: =IFERROR(__xludf.DUMMYFUNCTION("""COMPUTED_VALUE"""),"Tidak jawab") -> Tidak jawab
A8: =IFERROR(__xludf.DUMMYFUNCTION("""COMPUTED_VALUE"""),46023.0) -> 46023 | B8: =IFERROR(__xludf.DUMMYFUNCTION("""COMPUTED_VALUE"""),"2601D007") -> 2601D007 | C8: =IFERROR(__xludf.DUMMYFUNCTION("""COMPUTED_VALUE"""),"Mia Bella") -> Mia Bella | D8: =IFERROR(__xludf.DUMMYFUNCTION("""COMPUTED_VALUE"""),"08133977533") -> 08133977533 | E8: =IFERROR(__xludf.DUMMYFUNCTION("""COMPUTED_VALUE"""),"Instagram") -> Instagram | F8: =IFERROR(__xludf.DUMMYFUNCTION("""COMPUTED_VALUE"""),"Gagal") -> Gagal | G8: =IFERROR(__xludf.DUMMYFUNCTION("""COMPUTED_VALUE"""),"Ijen Baluran one day trip") -> Ijen Baluran one day trip | H8: =IFERROR(__xludf.DUMMYFUNCTION("""COMPUTED_VALUE"""),46026.0) -> 46026 | I8: =IFERROR(__xludf.DUMMYFUNCTION("""COMPUTED_VALUE"""),2.0) -> 2 | K8: =IFERROR(__xludf.DUMMYFUNCTION("""COMPUTED_VALUE"""),"1 wni 1 wna, tdk jawab") -> 1 wni 1 wna, tdk jawab
A9: =IFERROR(__xludf.DUMMYFUNCTION("""COMPUTED_VALUE"""),46023.0) -> 46023 | B9: =IFERROR(__xludf.DUMMYFUNCTION("""COMPUTED_VALUE"""),"2601D008") -> 2601D008 | C9: =IFERROR(__xludf.DUMMYFUNCTION("""COMPUTED_VALUE"""),"Kai") -> Kai | D9: =IFERROR(__xludf.DUMMYFUNCTION("""COMPUTED_VALUE"""),"081399930501") -> 081399930501 | E9: =IFERROR(__xludf.DUMMYFUNCTION("""COMPUTED_VALUE"""),"Instagram") -> Instagram | F9: =IFERROR(__xludf.DUMMYFUNCTION("""COMPUTED_VALUE"""),"Gagal") -> Gagal | G9: =IFERROR(__xludf.DUMMYFUNCTION("""COMPUTED_VALUE"""),"ot 3h2m") -> ot 3h2m | K9: =IFERROR(__xludf.DUMMYFUNCTION("""COMPUTED_VALUE"""),"lewat tanggal") -> lewat tanggal
A10: =IFERROR(__xludf.DUMMYFUNCTION("""COMPUTED_VALUE"""),46024.0) -> 46024 | B10: =IFERROR(__xludf.DUMMYFUNCTION("""COMPUTED_VALUE"""),"2601D009") -> 2601D009 | C10: =IFERROR(__xludf.DUMMYFUNCTION("""COMPUTED_VALUE"""),"Iin Noor Chozin") -> Iin Noor Chozin | D10: =IFERROR(__xludf.DUMMYFUNCTION("""COMPUTED_VALUE"""),"081233197590") -> 081233197590 | E10: =IFERROR(__xludf.DUMMYFUNCTION("""COMPUTED_VALUE"""),"Website") -> Website | F10: =IFERROR(__xludf.DUMMYFUNCTION("""COMPUTED_VALUE"""),"Closing") -> Closing | G10: =IFERROR(__xludf.DUMMYFUNCTION("""COMPUTED_VALUE"""),"Trip Menjangan Tabuhan") -> Trip Menjangan Tabuhan | H10: =IFERROR(__xludf.DUMMYFUNCTION("""COMPUTED_VALUE"""),46025.0) -> 46025 | I10: =IFERROR(__xludf.DUMMYFUNCTION("""COMPUTED_VALUE"""),6.0) -> 6 | J10: =IFERROR(__xludf.DUMMYFUNCTION("""COMPUTED_VALUE"""),2460000.0) -> 2460000 | K10: =IFERROR(__xludf.DUMMYFUNCTION("""COMPUTED_VALUE"""),"menjangan tabuhan") -> menjangan tabuhan
A11: =IFERROR(__xludf.DUMMYFUNCTION("""COMPUTED_VALUE"""),46024.0) -> 46024 | B11: =IFERROR(__xludf.DUMMYFUNCTION("""COMPUTED_VALUE"""),"2601D010") -> 2601D010 | C11: =IFERROR(__xludf.DUMMYFUNCTION("""COMPUTED_VALUE"""),"Dia Pur's") -> Dia Pur's | D11: =IFERROR(__xludf.DUMMYFUNCTION("""COMPUTED_VALUE"""),"082360390604") -> 082360390604 | E11: =IFERROR(__xludf.DUMMYFUNCTION("""COMPUTED_VALUE"""),"Instagram") -> Instagram | F11: =IFERROR(__xludf.DUMMYFUNCTION("""COMPUTED_VALUE"""),"Gagal") -> Gagal | G11: =IFERROR(__xludf.DUMMYFUNCTION("""COMPUTED_VALUE"""),"custom 2h1m") -> custom 2h1m | I11: =IFERROR(__xludf.DUMMYFUNCTION("""COMPUTED_VALUE"""),4.0) -> 4 | K11: =IFERROR(__xludf.DUMMYFUNCTION("""COMPUTED_VALUE"""),"tanggal lewat") -> tanggal lewat
A12: =IFERROR(__xludf.DUMMYFUNCTION("""COMPUTED_VALUE"""),46024.0) -> 46024 | B12: =IFERROR(__xludf.DUMMYFUNCTION("""COMPUTED_VALUE"""),"2601D011") -> 2601D011 | C12: =IFERROR(__xludf.DUMMYFUNCTION("""COMPUTED_VALUE"""),"Inggrid") -> Inggrid | D12: =IFERROR(__xludf.DUMMYFUNCTION("""COMPUTED_VALUE"""),"085156507128") -> 085156507128 | E12: =IFERROR(__xludf.DUMMYFUNCTION("""COMPUTED_VALUE"""),"Instagram") -> Instagram | F12: =IFERROR(__xludf.DUMMYFUNCTION("""COMPUTED_VALUE"""),"Gagal") -> Gagal | G12: =IFERROR(__xludf.DUMMYFUNCTION("""COMPUTED_VALUE"""),"OT Januari") -> OT Januari | K12: =IFERROR(__xludf.DUMMYFUNCTION("""COMPUTED_VALUE"""),"tidak jawab") -> tidak jawab
A13: =IFERROR(__xludf.DUMMYFUNCTION("""COMPUTED_VALUE"""),46024.0) -> 46024 | B13: =IFERROR(__xludf.DUMMYFUNCTION("""COMPUTED_VALUE"""),"2601D012") -> 2601D012 | C13: =IFERROR(__xludf.DUMMYFUNCTION("""COMPUTED_VALUE"""),"Kartika") -> Kartika | D13: =IFERROR(__xludf.DUMMYFUNCTION("""COMPUTED_VALUE"""),"082143617625") -> 082143617625 | E13: =IFERROR(__xludf.DUMMYFUNCTION("""COMPUTED_VALUE"""),"Website") -> Website | F13: =IFERROR(__xludf.DUMMYFUNCTION("""COMPUTED_VALUE"""),"Closing") -> Closing | G13: =IFERROR(__xludf.DUMMYFUNCTION("""COMPUTED_VALUE"""),"OT Menjangan Tabuhan") -> OT Menjangan Tabuhan | H13: =IFERROR(__xludf.DUMMYFUNCTION("""COMPUTED_VALUE"""),46033.0) -> 46033 | I13: =IFERROR(__xludf.DUMMYFUNCTION("""COMPUTED_VALUE"""),4.0) -> 4 | J13: =IFERROR(__xludf.DUMMYFUNCTION("""COMPUTED_VALUE"""),1180000.0) -> 1180000
A14: =IFERROR(__xludf.DUMMYFUNCTION("""COMPUTED_VALUE"""),46024.0) -> 46024 | B14: =IFERROR(__xludf.DUMMYFUNCTION("""COMPUTED_VALUE"""),"2601D013") -> 2601D013 | C14: =IFERROR(__xludf.DUMMYFUNCTION("""COMPUTED_VALUE"""),"Diyatrana") -> Diyatrana | D14: =IFERROR(__xludf.DUMMYFUNCTION("""COMPUTED_VALUE"""),"085729990708") -> 085729990708 | E14: =IFERROR(__xludf.DUMMYFUNCTION("""COMPUTED_VALUE"""),"Instagram") -> Instagram | F14: =IFERROR(__xludf.DUMMYFUNCTION("""COMPUTED_VALUE"""),"Gagal") -> Gagal | G14: =IFERROR(__xludf.DUMMYFUNCTION("""COMPUTED_VALUE"""),"3H2M opsi A") -> 3H2M opsi A | K14: =IFERROR(__xludf.DUMMYFUNCTION("""COMPUTED_VALUE"""),"tidak jawab") -> tidak jawab
A15: =IFERROR(__xludf.DUMMYFUNCTION("""COMPUTED_VALUE"""),46024.0) -> 46024 | B15: =IFERROR(__xludf.DUMMYFUNCTION("""COMPUTED_VALUE"""),"2601D014") -> 2601D014 | C15: =IFERROR(__xludf.DUMMYFUNCTION("""COMPUTED_VALUE"""),"Peni") -> Peni | D15: =IFERROR(__xludf.DUMMYFUNCTION("""COMPUTED_VALUE"""),"081553992808") -> 081553992808 | E15: =IFERROR(__xludf.DUMMYFUNCTION("""COMPUTED_VALUE"""),"Instagram") -> Instagram | F15: =IFERROR(__xludf.DUMMYFUNCTION("""COMPUTED_VALUE"""),"Gagal") -> Gagal | G15: =IFERROR(__xludf.DUMMYFUNCTION("""COMPUTED_VALUE"""),"Trip Pulau Bedil") -> Trip Pulau Bedil | H15: =IFERROR(__xludf.DUMMYFUNCTION("""COMPUTED_VALUE"""),46104.0) -> 46104 | I15: =IFERROR(__xludf.DUMMYFUNCTION("""COMPUTED_VALUE"""),4.0) -> 4 | J15: =IFERROR(__xludf.DUMMYFUNCTION("""COMPUTED_VALUE"""),1408000.0) -> 1408000 | K15: =IFERROR(__xludf.DUMMYFUNCTION("""COMPUTED_VALUE"""),"pindah haluan liburan") -> pindah haluan liburan
A16: =IFERROR(__xludf.DUMMYFUNCTION("""COMPUTED_VALUE"""),46024.0) -> 46024 | B16: =IFERROR(__xludf.DUMMYFUNCTION("""COMPUTED_VALUE"""),"2601D015") -> 2601D015 | C16: =IFERROR(__xludf.DUMMYFUNCTION("""COMPUTED_VALUE"""),"Kirana") -> Kirana | D16: =IFERROR(__xludf.DUMMYFUNCTION("""COMPUTED_VALUE"""),"085777785090") -> 085777785090 | E16: =IFERROR(__xludf.DUMMYFUNCTION("""COMPUTED_VALUE"""),"Website") -> Website | F16: =IFERROR(__xludf.DUMMYFUNCTION("""COMPUTED_VALUE"""),"Review") -> Review | G16: =IFERROR(__xludf.DUMMYFUNCTION("""COMPUTED_VALUE"""),"custom 2h1m") -> custom 2h1m | I16: =IFERROR(__xludf.DUMMYFUNCTION("""COMPUTED_VALUE"""),40.0) -> 40 | J16: =IFERROR(__xludf.DUMMYFUNCTION("""COMPUTED_VALUE"""),4.10244E7) -> 41024400 | K16: =IFERROR(__xludf.DUMMYFUNCTION("""COMPUTED_VALUE"""),"MINTA PAKET, fu akhir januari") -> MINTA PAKET, fu akhir januari
A17: =IFERROR(__xludf.DUMMYFUNCTION("""COMPUTED_VALUE"""),46024.0) -> 46024 | B17: =IFERROR(__xludf.DUMMYFUNCTION("""COMPUTED_VALUE"""),"2601D016") -> 2601D016 | C17: =IFERROR(__xludf.DUMMYFUNCTION("""COMPUTED_VALUE"""),"Ika W/ Ibu ms Nasir") -> Ika W/ Ibu ms Nasir | D17: =IFERROR(__xludf.DUMMYFUNCTION("""COMPUTED_VALUE"""),"0882007680200") -> 0882007680200 | E17: =IFERROR(__xludf.DUMMYFUNCTION("""COMPUTED_VALUE"""),"Website") -> Website | F17: =IFERROR(__xludf.DUMMYFUNCTION("""COMPUTED_VALUE"""),"Gagal") -> Gagal | G17: =IFERROR(__xludf.DUMMYFUNCTION("""COMPUTED_VALUE"""),"2H1M opsi C") -> 2H1M opsi C | H17: =IFERROR(__xludf.DUMMYFUNCTION("""COMPUTED_VALUE"""),46170.0) -> 46170 | I17: =IFERROR(__xludf.DUMMYFUNCTION("""COMPUTED_VALUE"""),17.0) -> 17 | K17: =IFERROR(__xludf.DUMMYFUNCTION("""COMPUTED_VALUE"""),"ganti ke bromo") -> ganti ke bromo
A18: =IFERROR(__xludf.DUMMYFUNCTION("""COMPUTED_VALUE"""),46024.0) -> 46024 | B18: =IFERROR(__xludf.DUMMYFUNCTION("""COMPUTED_VALUE"""),"2601D017") -> 2601D017 | C18: =IFERROR(__xludf.DUMMYFUNCTION("""COMPUTED_VALUE"""),"Karen") -> Karen | D18: =IFERROR(__xludf.DUMMYFUNCTION("""COMPUTED_VALUE"""),"087772484641") -> 087772484641 | E18: =IFERROR(__xludf.DUMMYFUNCTION("""COMPUTED_VALUE"""),"Instagram") -> Instagram | F18: =IFERROR(__xludf.DUMMYFUNCTION("""COMPUTED_VALUE"""),"Gagal") -> Gagal | G18: =IFERROR(__xludf.DUMMYFUNCTION("""COMPUTED_VALUE"""),"2 paket open trip") -> 2 paket open trip | I18: =IFERROR(__xludf.DUMMYFUNCTION("""COMPUTED_VALUE"""),2.0) -> 2 | J18: =IFERROR(__xludf.DUMMYFUNCTION("""COMPUTED_VALUE"""),1050000.0) -> 1050000 | K18: =IFERROR(__xludf.DUMMYFUNCTION("""COMPUTED_VALUE"""),"follow up tanggal 15 februari") -> follow up tanggal 15 februari
A19: =IFERROR(__xludf.DUMMYFUNCTION("""COMPUTED_VALUE"""),46024.0) -> 46024 | B19: =IFERROR(__xludf.DUMMYFUNCTION("""COMPUTED_VALUE"""),"2601D018") -> 2601D018 | C19: =IFERROR(__xludf.DUMMYFUNCTION("""COMPUTED_VALUE"""),"Tiyas") -> Tiyas | D19: =IFERROR(__xludf.DUMMYFUNCTION("""COMPUTED_VALUE"""),"082136195477") -> 082136195477 | E19: =IFERROR(__xludf.DUMMYFUNCTION("""COMPUTED_VALUE"""),"Lainnya") -> Lainnya | F19: =IFERROR(__xludf.DUMMYFUNCTION("""COMPUTED_VALUE"""),"Gagal") -> Gagal | G19: =IFERROR(__xludf.DUMMYFUNCTION("""COMPUTED_VALUE"""),"Custom 2h1m") -> Custom 2h1m | I19: =IFERROR(__xludf.DUMMYFUNCTION("""COMPUTED_VALUE"""),2.0) -> 2 | K19: =IFERROR(__xludf.DUMMYFUNCTION("""COMPUTED_VALUE"""),"Minta Paket, fu tgl 10") -> Minta Paket, fu tgl 10
A20: =IFERROR(__xludf.DUMMYFUNCTION("""COMPUTED_VALUE"""),46025.0) -> 46025 | B20: =IFERROR(__xludf.DUMMYFUNCTION("""COMPUTED_VALUE"""),"2601D019") -> 2601D019 | C20: =IFERROR(__xludf.DUMMYFUNCTION("""COMPUTED_VALUE"""),"Beta Amrina") -> Beta Amrina | D20: =IFERROR(__xludf.DUMMYFUNCTION("""COMPUTED_VALUE"""),"082327577538") -> 082327577538 | E20: =IFERROR(__xludf.DUMMYFUNCTION("""COMPUTED_VALUE"""),"Instagram") -> Instagram | F20: =IFERROR(__xludf.DUMMYFUNCTION("""COMPUTED_VALUE"""),"Gagal") -> Gagal | G20: =IFERROR(__xludf.DUMMYFUNCTION("""COMPUTED_VALUE"""),"OT") -> OT | I20: =IFERROR(__xludf.DUMMYFUNCTION("""COMPUTED_VALUE"""),3.0) -> 3 | J20: =IFERROR(__xludf.DUMMYFUNCTION("""COMPUTED_VALUE"""),4800000.0) -> 4800000 | K20: =IFERROR(__xludf.DUMMYFUNCTION("""COMPUTED_VALUE"""),"tidak jawab") -> tidak jawab
A21: =IFERROR(__xludf.DUMMYFUNCTION("""COMPUTED_VALUE"""),46025.0) -> 46025 | B21: =IFERROR(__xludf.DUMMYFUNCTION("""COMPUTED_VALUE"""),"2601D020") -> 2601D020 | C21: =IFERROR(__xludf.DUMMYFUNCTION("""COMPUTED_VALUE"""),"Wa ") -> Wa | D21: =IFERROR(__xludf.DUMMYFUNCTION("""COMPUTED_VALUE"""),"085641568779") -> 085641568779 | E21: =IFERROR(__xludf.DUMMYFUNCTION("""COMPUTED_VALUE"""),"Lainnya") -> Lainnya | F21: =IFERROR(__xludf.DUMMYFUNCTION("""COMPUTED_VALUE"""),"Gagal") -> Gagal | G21: =IFERROR(__xludf.DUMMYFUNCTION("""COMPUTED_VALUE"""),"ot djawatan baluran") -> ot djawatan baluran | K21: =IFERROR(__xludf.DUMMYFUNCTION("""COMPUTED_VALUE"""),"tidak jawab") -> tidak jawab
A22: =IFERROR(__xludf.DUMMYFUNCTION("""COMPUTED_VALUE"""),46025.0) -> 46025 | B22: =IFERROR(__xludf.DUMMYFUNCTION("""COMPUTED_VALUE"""),"2601D021") -> 2601D021 | C22: =IFERROR(__xludf.DUMMYFUNCTION("""COMPUTED_VALUE"""),"Buds") -> Buds | D22: =IFERROR(__xludf.DUMMYFUNCTION("""COMPUTED_VALUE"""),"085720585703") -> 085720585703 | E22: =IFERROR(__xludf.DUMMYFUNCTION("""COMPUTED_VALUE"""),"Website") -> Website | F22: =IFERROR(__xludf.DUMMYFUNCTION("""COMPUTED_VALUE"""),"Gagal") -> Gagal | G22: =IFERROR(__xludf.DUMMYFUNCTION("""COMPUTED_VALUE"""),"Baluran private ") -> Baluran private | K22: =IFERROR(__xludf.DUMMYFUNCTION("""COMPUTED_VALUE"""),"tidak jawab") -> tidak jawab
A23: =IFERROR(__xludf.DUMMYFUNCTION("""COMPUTED_VALUE"""),46025.0) -> 46025 | B23: =IFERROR(__xludf.DUMMYFUNCTION("""COMPUTED_VALUE"""),"2601D022") -> 2601D022 | C23: =IFERROR(__xludf.DUMMYFUNCTION("""COMPUTED_VALUE"""),"Seysa") -> Seysa | D23: =IFERROR(__xludf.DUMMYFUNCTION("""COMPUTED_VALUE"""),"085886980015") -> 085886980015 | E23: =IFERROR(__xludf.DUMMYFUNCTION("""COMPUTED_VALUE"""),"Instagram") -> Instagram | F23: =IFERROR(__xludf.DUMMYFUNCTION("""COMPUTED_VALUE"""),"Gagal") -> Gagal | G23: =IFERROR(__xludf.DUMMYFUNCTION("""COMPUTED_VALUE"""),"trip kawah wurung") -> trip kawah wurung | H23: =IFERROR(__xludf.DUMMYFUNCTION("""COMPUTED_VALUE"""),46028.0) -> 46028 | I23: =IFERROR(__xludf.DUMMYFUNCTION("""COMPUTED_VALUE"""),3.0) -> 3 | K23: =IFERROR(__xludf.DUMMYFUNCTION("""COMPUTED_VALUE"""),"masih pikir2 dulu, sudah lewat tgl") -> masih pikir2 dulu, sudah lewat tgl
A24: =IFERROR(__xludf.DUMMYFUNCTION("""COMPUTED_VALUE"""),46025.0) -> 46025 | B24: =IFERROR(__xludf.DUMMYFUNCTION("""COMPUTED_VALUE"""),"2601D023") -> 2601D023 | C24: =IFERROR(__xludf.DUMMYFUNCTION("""COMPUTED_VALUE"""),"Nothing") -> Nothing | D24: =IFERROR(__xludf.DUMMYFUNCTION("""COMPUTED_VALUE"""),"085820515179") -> 085820515179 | E24: =IFERROR(__xludf.DUMMYFUNCTION("""COMPUTED_VALUE"""),"Website") -> Website | F24: =IFERROR(__xludf.DUMMYFUNCTION("""COMPUTED_VALUE"""),"Gagal") -> Gagal | G24: =IFERROR(__xludf.DUMMYFUNCTION("""COMPUTED_VALUE"""),"Trip Kawah Ijen") -> Trip Kawah Ijen | K24: =IFERROR(__xludf.DUMMYFUNCTION("""COMPUTED_VALUE"""),"mepo sby atau gresik") -> mepo sby atau gresik
A25: =IFERROR(__xludf.DUMMYFUNCTION("""COMPUTED_VALUE"""),46025.0) -> 46025 | B25: =IFERROR(__xludf.DUMMYFUNCTION("""COMPUTED_VALUE"""),"2601D024") -> 2601D024 | C25: =IFERROR(__xludf.DUMMYFUNCTION("""COMPUTED_VALUE"""),"Dhevy Hariady") -> Dhevy Hariady | D25: =IFERROR(__xludf.DUMMYFUNCTION("""COMPUTED_VALUE"""),"082282391601") -> 082282391601 | E25: =IFERROR(__xludf.DUMMYFUNCTION("""COMPUTED_VALUE"""),"Instagram") -> Instagram | F25: =IFERROR(__xludf.DUMMYFUNCTION("""COMPUTED_VALUE"""),"Gagal") -> Gagal | G25: =IFERROR(__xludf.DUMMYFUNCTION("""COMPUTED_VALUE"""),"trip djawatan baluran") -> trip djawatan baluran | I25: =IFERROR(__xludf.DUMMYFUNCTION("""COMPUTED_VALUE"""),4.0) -> 4 | J25: =IFERROR(__xludf.DUMMYFUNCTION("""COMPUTED_VALUE"""),1996000.0) -> 1996000 | K25: =IFERROR(__xludf.DUMMYFUNCTION("""COMPUTED_VALUE"""),"tidak jadi liburan ke BWI") -> tidak jadi liburan ke BWI | L25: =IFERROR(__xludf.DUMMYFUNCTION("""COMPUTED_VALUE"""),"https://docs.google.com/document/d/1wA6Vstebr_OPv-YiZuHCtRJ0dphAaw92AabZKFpW9i0/edit?tab=t.0") -> https://docs.google.com/document/d/1wA6Vstebr_OPv-YiZuHCtRJ0dphAaw92AabZKFpW9i0/edit?tab=t.0
A26: =IFERROR(__xludf.DUMMYFUNCTION("""COMPUTED_VALUE"""),46025.0) -> 46025 | B26: =IFERROR(__xludf.DUMMYFUNCTION("""COMPUTED_VALUE"""),"2601D025") -> 2601D025 | C26: =IFERROR(__xludf.DUMMYFUNCTION("""COMPUTED_VALUE"""),"Ratu (Bunda FazZZam)") -> Ratu (Bunda FazZZam) | D26: =IFERROR(__xludf.DUMMYFUNCTION("""COMPUTED_VALUE"""),"081806567775") -> 081806567775 | E26: =IFERROR(__xludf.DUMMYFUNCTION("""COMPUTED_VALUE"""),"Instagram") -> Instagram | F26: =IFERROR(__xludf.DUMMYFUNCTION("""COMPUTED_VALUE"""),"Gagal") -> Gagal | G26: =IFERROR(__xludf.DUMMYFUNCTION("""COMPUTED_VALUE"""),"OT 3H2M") -> OT 3H2M | K26: =IFERROR(__xludf.DUMMYFUNCTION("""COMPUTED_VALUE"""),"masih ngomong ke atasan") -> masih ngomong ke atasan
A27: =IFERROR(__xludf.DUMMYFUNCTION("""COMPUTED_VALUE"""),46025.0) -> 46025 | B27: =IFERROR(__xludf.DUMMYFUNCTION("""COMPUTED_VALUE"""),"2601D026") -> 2601D026 | C27: =IFERROR(__xludf.DUMMYFUNCTION("""COMPUTED_VALUE"""),"Gilang") -> Gilang | D27: =IFERROR(__xludf.DUMMYFUNCTION("""COMPUTED_VALUE"""),"081221614470") -> 081221614470 | E27: =IFERROR(__xludf.DUMMYFUNCTION("""COMPUTED_VALUE"""),"Website") -> Website | F27: =IFERROR(__xludf.DUMMYFUNCTION("""COMPUTED_VALUE"""),"Closing") -> Closing | G27: =IFERROR(__xludf.DUMMYFUNCTION("""COMPUTED_VALUE"""),"Private Trip Kawah Wurung") -> Private Trip Kawah Wurung | H27: =IFERROR(__xludf.DUMMYFUNCTION("""COMPUTED_VALUE"""),46026.0) -> 46026 | I27: =IFERROR(__xludf.DUMMYFUNCTION("""COMPUTED_VALUE"""),1.0) -> 1 | J27: =IFERROR(__xludf.DUMMYFUNCTION("""COMPUTED_VALUE"""),2318100.0) -> 2318100
A28: =IFERROR(__xludf.DUMMYFUNCTION("""COMPUTED_VALUE"""),46025.0) -> 46025 | B28: =IFERROR(__xludf.DUMMYFUNCTION("""COMPUTED_VALUE"""),"2601D027") -> 2601D027 | C28: =IFERROR(__xludf.DUMMYFUNCTION("""COMPUTED_VALUE"""),"Farus nabil") -> Farus nabil | D28: =IFERROR(__xludf.DUMMYFUNCTION("""COMPUTED_VALUE"""),"081293944286") -> 081293944286 | E28: =IFERROR(__xludf.DUMMYFUNCTION("""COMPUTED_VALUE"""),"Instagram") -> Instagram | F28: =IFERROR(__xludf.DUMMYFUNCTION("""COMPUTED_VALUE"""),"Closing") -> Closing | G28: =IFERROR(__xludf.DUMMYFUNCTION("""COMPUTED_VALUE"""),"Private Trip Menjangan Tabuhan") -> Private Trip Menjangan Tabuhan | H28: =IFERROR(__xludf.DUMMYFUNCTION("""COMPUTED_VALUE"""),46032.0) -> 46032 | I28: =IFERROR(__xludf.DUMMYFUNCTION("""COMPUTED_VALUE"""),5.0) -> 5 | J28: =IFERROR(__xludf.DUMMYFUNCTION("""COMPUTED_VALUE"""),2300000.0) -> 2300000
A29: =IFERROR(__xludf.DUMMYFUNCTION("""COMPUTED_VALUE"""),46025.0) -> 46025 | B29: =IFERROR(__xludf.DUMMYFUNCTION("""COMPUTED_VALUE"""),"2601D028") -> 2601D028 | C29: =IFERROR(__xludf.DUMMYFUNCTION("""COMPUTED_VALUE"""),"Rehan") -> Rehan | D29: =IFERROR(__xludf.DUMMYFUNCTION("""COMPUTED_VALUE"""),"08963381584") -> 08963381584 | E29: =IFERROR(__xludf.DUMMYFUNCTION("""COMPUTED_VALUE"""),"Instagram") -> Instagram | F29: =IFERROR(__xludf.DUMMYFUNCTION("""COMPUTED_VALUE"""),"Gagal") -> Gagal | G29: =IFERROR(__xludf.DUMMYFUNCTION("""COMPUTED_VALUE"""),"2H1M") -> 2H1M | I29: =IFERROR(__xludf.DUMMYFUNCTION("""COMPUTED_VALUE"""),5.0) -> 5 | J29: =IFERROR(__xludf.DUMMYFUNCTION("""COMPUTED_VALUE"""),9225000.0) -> 9225000 | K29: =IFERROR(__xludf.DUMMYFUNCTION("""COMPUTED_VALUE"""),"tidak ada jawaban") -> tidak ada jawaban
A30: =IFERROR(__xludf.DUMMYFUNCTION("""COMPUTED_VALUE"""),46025.0) -> 46025 | B30: =IFERROR(__xludf.DUMMYFUNCTION("""COMPUTED_VALUE"""),"2601D029") -> 2601D029 | C30: =IFERROR(__xludf.DUMMYFUNCTION("""COMPUTED_VALUE"""),"Nella Holiday") -> Nella Holiday | D30: =IFERROR(__xludf.DUMMYFUNCTION("""COMPUTED_VALUE"""),"089672570321") -> 089672570321 | E30: =IFERROR(__xludf.DUMMYFUNCTION("""COMPUTED_VALUE"""),"Website") -> Website | F30: =IFERROR(__xludf.DUMMYFUNCTION("""COMPUTED_VALUE"""),"Gagal") -> Gagal | G30: =IFERROR(__xludf.DUMMYFUNCTION("""COMPUTED_VALUE"""),"trip ijen") -> trip ijen | H30: =IFERROR(__xludf.DUMMYFUNCTION("""COMPUTED_VALUE"""),46039.0) -> 46039 | I30: =IFERROR(__xludf.DUMMYFUNCTION("""COMPUTED_VALUE"""),14.0) -> 14 | K30: =IFERROR(__xludf.DUMMYFUNCTION("""COMPUTED_VALUE"""),"SDH FOLLOW UP") -> SDH FOLLOW UP
A31: =IFERROR(__xludf.DUMMYFUNCTION("""COMPUTED_VALUE"""),46026.0) -> 46026 | B31: =IFERROR(__xludf.DUMMYFUNCTION("""COMPUTED_VALUE"""),"2601D030") -> 2601D030 | C31: =IFERROR(__xludf.DUMMYFUNCTION("""COMPUTED_VALUE"""),"Cika") -> Cika | D31: =IFERROR(__xludf.DUMMYFUNCTION("""COMPUTED_VALUE"""),"085782656823") -> 085782656823 | E31: =IFERROR(__xludf.DUMMYFUNCTION("""COMPUTED_VALUE"""),"Instagram") -> Instagram | F31: =IFERROR(__xludf.DUMMYFUNCTION("""COMPUTED_VALUE"""),"Gagal") -> Gagal | G31: =IFERROR(__xludf.DUMMYFUNCTION("""COMPUTED_VALUE"""),"Trip 3H2M") -> Trip 3H2M | K31: =IFERROR(__xludf.DUMMYFUNCTION("""COMPUTED_VALUE"""),"tidak ada jawaban") -> tidak ada jawaban
A32: =IFERROR(__xludf.DUMMYFUNCTION("""COMPUTED_VALUE"""),46026.0) -> 46026 | B32: =IFERROR(__xludf.DUMMYFUNCTION("""COMPUTED_VALUE"""),"2601D031") -> 2601D031 | C32: =IFERROR(__xludf.DUMMYFUNCTION("""COMPUTED_VALUE"""),"Sulistio W.N") -> Sulistio W.N | D32: =IFERROR(__xludf.DUMMYFUNCTION("""COMPUTED_VALUE"""),"082137405814") -> 082137405814 | E32: =IFERROR(__xludf.DUMMYFUNCTION("""COMPUTED_VALUE"""),"Website") -> Website | F32: =IFERROR(__xludf.DUMMYFUNCTION("""COMPUTED_VALUE"""),"Gagal") -> Gagal | G32: =IFERROR(__xludf.DUMMYFUNCTION("""COMPUTED_VALUE"""),"3H2M opsi B") -> 3H2M opsi B | K32: =IFERROR(__xludf.DUMMYFUNCTION("""COMPUTED_VALUE"""),"tanya yacht boom, fu tgl 15") -> tanya yacht boom, fu tgl 15
A33: =IFERROR(__xludf.DUMMYFUNCTION("""COMPUTED_VALUE"""),46026.0) -> 46026 | B33: =IFERROR(__xludf.DUMMYFUNCTION("""COMPUTED_VALUE"""),"2601D032") -> 2601D032 | C33: =IFERROR(__xludf.DUMMYFUNCTION("""COMPUTED_VALUE"""),"Thata Anggitha") -> Thata Anggitha | D33: =IFERROR(__xludf.DUMMYFUNCTION("""COMPUTED_VALUE"""),"082137405814") -> 082137405814 | E33: =IFERROR(__xludf.DUMMYFUNCTION("""COMPUTED_VALUE"""),"Instagram") -> Instagram | F33: =IFERROR(__xludf.DUMMYFUNCTION("""COMPUTED_VALUE"""),"Gagal") -> Gagal | I33: =IFERROR(__xludf.DUMMYFUNCTION("""COMPUTED_VALUE"""),2.0) -> 2 | K33: =IFERROR(__xludf.DUMMYFUNCTION("""COMPUTED_VALUE"""),"sudah follow up") -> sudah follow up
A34: =IFERROR(__xludf.DUMMYFUNCTION("""COMPUTED_VALUE"""),46026.0) -> 46026 | B34: =IFERROR(__xludf.DUMMYFUNCTION("""COMPUTED_VALUE"""),"2601D033") -> 2601D033 | C34: =IFERROR(__xludf.DUMMYFUNCTION("""COMPUTED_VALUE"""),"Aris Guntoro") -> Aris Guntoro | D34: =IFERROR(__xludf.DUMMYFUNCTION("""COMPUTED_VALUE"""),"081355209321") -> 081355209321 | E34: =IFERROR(__xludf.DUMMYFUNCTION("""COMPUTED_VALUE"""),"Website") -> Website | F34: =IFERROR(__xludf.DUMMYFUNCTION("""COMPUTED_VALUE"""),"Closing") -> Closing | G34: =IFERROR(__xludf.DUMMYFUNCTION("""COMPUTED_VALUE"""),"Trip Kawah Ijen") -> Trip Kawah Ijen | H34: =IFERROR(__xludf.DUMMYFUNCTION("""COMPUTED_VALUE"""),46038.0) -> 46038 | I34: =IFERROR(__xludf.DUMMYFUNCTION("""COMPUTED_VALUE"""),4.0) -> 4 | J34: =IFERROR(__xludf.DUMMYFUNCTION("""COMPUTED_VALUE"""),1570000.0) -> 1570000 | K34: =IFERROR(__xludf.DUMMYFUNCTION("""COMPUTED_VALUE"""),"sudah closing") -> sudah closing
A35: =IFERROR(__xludf.DUMMYFUNCTION("""COMPUTED_VALUE"""),46026.0) -> 46026 | B35: =IFERROR(__xludf.DUMMYFUNCTION("""COMPUTED_VALUE"""),"2601D034") -> 2601D034 | C35: =IFERROR(__xludf.DUMMYFUNCTION("""COMPUTED_VALUE"""),"Rizal Pratama") -> Rizal Pratama | D35: =IFERROR(__xludf.DUMMYFUNCTION("""COMPUTED_VALUE"""),"082216912039") -> 082216912039 | E35: =IFERROR(__xludf.DUMMYFUNCTION("""COMPUTED_VALUE"""),"Instagram") -> Instagram | F35: =IFERROR(__xludf.DUMMYFUNCTION("""COMPUTED_VALUE"""),"Gagal") -> Gagal | G35: =IFERROR(__xludf.DUMMYFUNCTION("""COMPUTED_VALUE"""),"3H2M opsi A") -> 3H2M opsi A | I35: =IFERROR(__xludf.DUMMYFUNCTION("""COMPUTED_VALUE"""),30.0) -> 30 | K35: =IFERROR(__xludf.DUMMYFUNCTION("""COMPUTED_VALUE"""),"sudah sm rekan lain") -> sudah sm rekan lain
A36: =IFERROR(__xludf.DUMMYFUNCTION("""COMPUTED_VALUE"""),46026.0) -> 46026 | B36: =IFERROR(__xludf.DUMMYFUNCTION("""COMPUTED_VALUE"""),"2601D035") -> 2601D035 | C36: =IFERROR(__xludf.DUMMYFUNCTION("""COMPUTED_VALUE"""),"Surya") -> Surya | D36: =IFERROR(__xludf.DUMMYFUNCTION("""COMPUTED_VALUE"""),"081803536960") -> 081803536960 | E36: =IFERROR(__xludf.DUMMYFUNCTION("""COMPUTED_VALUE"""),"Website") -> Website | F36: =IFERROR(__xludf.DUMMYFUNCTION("""COMPUTED_VALUE"""),"Gagal") -> Gagal | G36: =IFERROR(__xludf.DUMMYFUNCTION("""COMPUTED_VALUE"""),"Trip Menjangan Tabuhan ") -> Trip Menjangan Tabuhan | I36: =IFERROR(__xludf.DUMMYFUNCTION("""COMPUTED_VALUE"""),25.0) -> 25 | K36: =IFERROR(__xludf.DUMMYFUNCTION("""COMPUTED_VALUE"""),"tidak cocok harga") -> tidak cocok harga
A37: =IFERROR(__xludf.DUMMYFUNCTION("""COMPUTED_VALUE"""),46026.0) -> 46026 | B37: =IFERROR(__xludf.DUMMYFUNCTION("""COMPUTED_VALUE"""),"2601D036") -> 2601D036 | C37: =IFERROR(__xludf.DUMMYFUNCTION("""COMPUTED_VALUE"""),"Yaya") -> Yaya | D37: =IFERROR(__xludf.DUMMYFUNCTION("""COMPUTED_VALUE"""),"089612554076") -> 089612554076 | E37: =IFERROR(__xludf.DUMMYFUNCTION("""COMPUTED_VALUE"""),"Instagram") -> Instagram | F37: =IFERROR(__xludf.DUMMYFUNCTION("""COMPUTED_VALUE"""),"Gagal") -> Gagal | G37: =IFERROR(__xludf.DUMMYFUNCTION("""COMPUTED_VALUE"""),"OT 3H2M") -> OT 3H2M | K37: =IFERROR(__xludf.DUMMYFUNCTION("""COMPUTED_VALUE"""),"tidak jawab") -> tidak jawab
A38: =IFERROR(__xludf.DUMMYFUNCTION("""COMPUTED_VALUE"""),46026.0) -> 46026 | B38: =IFERROR(__xludf.DUMMYFUNCTION("""COMPUTED_VALUE"""),"2601D037") -> 2601D037 | C38: =IFERROR(__xludf.DUMMYFUNCTION("""COMPUTED_VALUE"""),"Hums GPS Malang") -> Hums GPS Malang | D38: =IFERROR(__xludf.DUMMYFUNCTION("""COMPUTED_VALUE"""),"085888433436") -> 085888433436 | E38: =IFERROR(__xludf.DUMMYFUNCTION("""COMPUTED_VALUE"""),"Instagram") -> Instagram | F38: =IFERROR(__xludf.DUMMYFUNCTION("""COMPUTED_VALUE"""),"Gagal") -> Gagal | G38: =IFERROR(__xludf.DUMMYFUNCTION("""COMPUTED_VALUE"""),"2H1M") -> 2H1M | K38: =IFERROR(__xludf.DUMMYFUNCTION("""COMPUTED_VALUE"""),"minta jpt sby") -> minta jpt sby
A39: =IFERROR(__xludf.DUMMYFUNCTION("""COMPUTED_VALUE"""),46026.0) -> 46026 | B39: =IFERROR(__xludf.DUMMYFUNCTION("""COMPUTED_VALUE"""),"2601D038") -> 2601D038 | C39: =IFERROR(__xludf.DUMMYFUNCTION("""COMPUTED_VALUE"""),"Sary Maheswari") -> Sary Maheswari | D39: =IFERROR(__xludf.DUMMYFUNCTION("""COMPUTED_VALUE"""),"085729077777") -> 085729077777 | E39: =IFERROR(__xludf.DUMMYFUNCTION("""COMPUTED_VALUE"""),"Instagram") -> Instagram | F39: =IFERROR(__xludf.DUMMYFUNCTION("""COMPUTED_VALUE"""),"Gagal") -> Gagal | G39: =IFERROR(__xludf.DUMMYFUNCTION("""COMPUTED_VALUE"""),"2H1M") -> 2H1M | I39: =IFERROR(__xludf.DUMMYFUNCTION("""COMPUTED_VALUE"""),6.0) -> 6 | K39: =IFERROR(__xludf.DUMMYFUNCTION("""COMPUTED_VALUE"""),"tanya paket, lewat tanggal") -> tanya paket, lewat tanggal
A40: =IFERROR(__xludf.DUMMYFUNCTION("""COMPUTED_VALUE"""),46027.0) -> 46027 | B40: =IFERROR(__xludf.DUMMYFUNCTION("""COMPUTED_VALUE"""),"2601D039") -> 2601D039 | C40: =IFERROR(__xludf.DUMMYFUNCTION("""COMPUTED_VALUE"""),"Tanamalintan ") -> Tanamalintan | D40: =IFERROR(__xludf.DUMMYFUNCTION("""COMPUTED_VALUE"""),"083877965575") -> 083877965575 | E40: =IFERROR(__xludf.DUMMYFUNCTION("""COMPUTED_VALUE"""),"Website") -> Website | F40: =IFERROR(__xludf.DUMMYFUNCTION("""COMPUTED_VALUE"""),"Gagal") -> Gagal | G40: =IFERROR(__xludf.DUMMYFUNCTION("""COMPUTED_VALUE"""),"2H1M") -> 2H1M | I40: =IFERROR(__xludf.DUMMYFUNCTION("""COMPUTED_VALUE"""),60.0) -> 60 | K40: =IFERROR(__xludf.DUMMYFUNCTION("""COMPUTED_VALUE"""),"tunda lebaran tahun depan") -> tunda lebaran tahun depan
...

Sheet Leads_Alvin
A1: =IFERROR(__xludf.DUMMYFUNCTION("QUERY( 'Input Data'!A1:N5505, ""select B, A, C, D, E, G, H, I, J, K, L, N where F = 'Alvin'"", 1 ) "),"TANGGAL") -> TANGGAL | B1: =IFERROR(__xludf.DUMMYFUNCTION("""COMPUTED_VALUE"""),"KODE") -> KODE | C1: =IFERROR(__xludf.DUMMYFUNCTION("""COMPUTED_VALUE"""),"NAMA") -> NAMA | D1: =IFERROR(__xludf.DUMMYFUNCTION("""COMPUTED_VALUE"""),"WHATSAPP") -> WHATSAPP | E1: =IFERROR(__xludf.DUMMYFUNCTION("""COMPUTED_VALUE"""),"SOURCE") -> SOURCE | F1: =IFERROR(__xludf.DUMMYFUNCTION("""COMPUTED_VALUE"""),"STATUS") -> STATUS | G1: =IFERROR(__xludf.DUMMYFUNCTION("""COMPUTED_VALUE"""),"PAKET / DESTINASI") -> PAKET / DESTINASI | H1: =IFERROR(__xludf.DUMMYFUNCTION("""COMPUTED_VALUE"""),"TANGGAL TRIP") -> TANGGAL TRIP | I1: =IFERROR(__xludf.DUMMYFUNCTION("""COMPUTED_VALUE"""),"PAX") -> PAX | J1: =IFERROR(__xludf.DUMMYFUNCTION("""COMPUTED_VALUE"""),"ESTIMASI NILAI ORDER") -> ESTIMASI NILAI ORDER | K1: =IFERROR(__xludf.DUMMYFUNCTION("""COMPUTED_VALUE"""),"KETERANGAN") -> KETERANGAN | L1: =IFERROR(__xludf.DUMMYFUNCTION("""COMPUTED_VALUE"""),"ANALISA AI") -> ANALISA AI
A2: =IFERROR(__xludf.DUMMYFUNCTION("""COMPUTED_VALUE"""),46023.0) -> 46023 | B2: =IFERROR(__xludf.DUMMYFUNCTION("""COMPUTED_VALUE"""),"2601A001") -> 2601A001 | C2: =IFERROR(__xludf.DUMMYFUNCTION("""COMPUTED_VALUE"""),"Cynthia") -> Cynthia | D2: =IFERROR(__xludf.DUMMYFUNCTION("""COMPUTED_VALUE"""),"081249880600") -> 081249880600 | E2: =IFERROR(__xludf.DUMMYFUNCTION("""COMPUTED_VALUE"""),"Website") -> Website | F2: =IFERROR(__xludf.DUMMYFUNCTION("""COMPUTED_VALUE"""),"Closing") -> Closing | G2: =IFERROR(__xludf.DUMMYFUNCTION("""COMPUTED_VALUE"""),"Menjangan Tabuhan") -> Menjangan Tabuhan | H2: =IFERROR(__xludf.DUMMYFUNCTION("""COMPUTED_VALUE"""),46025.0) -> 46025 | J2: =IFERROR(__xludf.DUMMYFUNCTION("""COMPUTED_VALUE"""),7905000.0) -> 7905000 | K2: =IFERROR(__xludf.DUMMYFUNCTION("""COMPUTED_VALUE"""),"tambah foto video") -> tambah foto video
A3: =IFERROR(__xludf.DUMMYFUNCTION("""COMPUTED_VALUE"""),46023.0) -> 46023 | B3: =IFERROR(__xludf.DUMMYFUNCTION("""COMPUTED_VALUE"""),"2601A002") -> 2601A002 | C3: =IFERROR(__xludf.DUMMYFUNCTION("""COMPUTED_VALUE"""),"Dewitri") -> Dewitri | D3: =IFERROR(__xludf.DUMMYFUNCTION("""COMPUTED_VALUE"""),"085776495791") -> 085776495791 | E3: =IFERROR(__xludf.DUMMYFUNCTION("""COMPUTED_VALUE"""),"Website") -> Website | F3: =IFERROR(__xludf.DUMMYFUNCTION("""COMPUTED_VALUE"""),"Gagal") -> Gagal | G3: =IFERROR(__xludf.DUMMYFUNCTION("""COMPUTED_VALUE"""),"Kawah ijen") -> Kawah ijen | H3: =IFERROR(__xludf.DUMMYFUNCTION("""COMPUTED_VALUE"""),46023.0) -> 46023 | I3: =IFERROR(__xludf.DUMMYFUNCTION("""COMPUTED_VALUE"""),3.0) -> 3
A4: =IFERROR(__xludf.DUMMYFUNCTION("""COMPUTED_VALUE"""),46024.0) -> 46024 | B4: =IFERROR(__xludf.DUMMYFUNCTION("""COMPUTED_VALUE"""),"2601A003") -> 2601A003 | C4: =IFERROR(__xludf.DUMMYFUNCTION("""COMPUTED_VALUE"""),"Ulil albab") -> Ulil albab | D4: =IFERROR(__xludf.DUMMYFUNCTION("""COMPUTED_VALUE"""),"08561542812") -> 08561542812 | E4: =IFERROR(__xludf.DUMMYFUNCTION("""COMPUTED_VALUE"""),"Website") -> Website | F4: =IFERROR(__xludf.DUMMYFUNCTION("""COMPUTED_VALUE"""),"Gagal") -> Gagal | G4: =IFERROR(__xludf.DUMMYFUNCTION("""COMPUTED_VALUE"""),"Trip MT") -> Trip MT | H4: =IFERROR(__xludf.DUMMYFUNCTION("""COMPUTED_VALUE"""),46024.0) -> 46024 | I4: =IFERROR(__xludf.DUMMYFUNCTION("""COMPUTED_VALUE"""),4.0) -> 4 | K4: =IFERROR(__xludf.DUMMYFUNCTION("""COMPUTED_VALUE"""),"Over budget") -> Over budget
A5: =IFERROR(__xludf.DUMMYFUNCTION("""COMPUTED_VALUE"""),46024.0) -> 46024 | B5: =IFERROR(__xludf.DUMMYFUNCTION("""COMPUTED_VALUE"""),"2601A004") -> 2601A004 | C5: =IFERROR(__xludf.DUMMYFUNCTION("""COMPUTED_VALUE"""),"Anto") -> Anto | D5: =IFERROR(__xludf.DUMMYFUNCTION("""COMPUTED_VALUE"""),"0818950503") -> 0818950503 | E5: =IFERROR(__xludf.DUMMYFUNCTION("""COMPUTED_VALUE"""),"Website") -> Website | F5: =IFERROR(__xludf.DUMMYFUNCTION("""COMPUTED_VALUE"""),"Gagal") -> Gagal | K5: =IFERROR(__xludf.DUMMYFUNCTION("""COMPUTED_VALUE"""),"jadinya ke malang") -> jadinya ke malang
A6: =IFERROR(__xludf.DUMMYFUNCTION("""COMPUTED_VALUE"""),46026.0) -> 46026 | B6: =IFERROR(__xludf.DUMMYFUNCTION("""COMPUTED_VALUE"""),"2601A005") -> 2601A005 | C6: =IFERROR(__xludf.DUMMYFUNCTION("""COMPUTED_VALUE"""),"Tjen bie") -> Tjen bie | D6: =IFERROR(__xludf.DUMMYFUNCTION("""COMPUTED_VALUE"""),"081330627337") -> 081330627337 | E6: =IFERROR(__xludf.DUMMYFUNCTION("""COMPUTED_VALUE"""),"Website") -> Website | F6: =IFERROR(__xludf.DUMMYFUNCTION("""COMPUTED_VALUE"""),"Gagal") -> Gagal | G6: =IFERROR(__xludf.DUMMYFUNCTION("""COMPUTED_VALUE"""),"3H2M Z") -> 3H2M Z | H6: =IFERROR(__xludf.DUMMYFUNCTION("""COMPUTED_VALUE"""),46027.0) -> 46027 | I6: =IFERROR(__xludf.DUMMYFUNCTION("""COMPUTED_VALUE"""),2.0) -> 2 | K6: =IFERROR(__xludf.DUMMYFUNCTION("""COMPUTED_VALUE"""),"Jadi ke lovina") -> Jadi ke lovina
A7: =IFERROR(__xludf.DUMMYFUNCTION("""COMPUTED_VALUE"""),46027.0) -> 46027 | B7: =IFERROR(__xludf.DUMMYFUNCTION("""COMPUTED_VALUE"""),"2601A006") -> 2601A006 | C7: =IFERROR(__xludf.DUMMYFUNCTION("""COMPUTED_VALUE"""),"Anindita purnamasari") -> Anindita purnamasari | D7: =IFERROR(__xludf.DUMMYFUNCTION("""COMPUTED_VALUE"""),"082233330301") -> 082233330301 | E7: =IFERROR(__xludf.DUMMYFUNCTION("""COMPUTED_VALUE"""),"Website") -> Website | F7: =IFERROR(__xludf.DUMMYFUNCTION("""COMPUTED_VALUE"""),"Gagal") -> Gagal | G7: =IFERROR(__xludf.DUMMYFUNCTION("""COMPUTED_VALUE"""),"2H1M") -> 2H1M | I7: =IFERROR(__xludf.DUMMYFUNCTION("""COMPUTED_VALUE"""),2.0) -> 2 | K7: =IFERROR(__xludf.DUMMYFUNCTION("""COMPUTED_VALUE"""),"dikabari jika jadi ambil paketnya") -> dikabari jika jadi ambil paketnya
A8: =IFERROR(__xludf.DUMMYFUNCTION("""COMPUTED_VALUE"""),46027.0) -> 46027 | B8: =IFERROR(__xludf.DUMMYFUNCTION("""COMPUTED_VALUE"""),"2601A007") -> 2601A007 | C8: =IFERROR(__xludf.DUMMYFUNCTION("""COMPUTED_VALUE"""),"Riska") -> Riska | D8: =IFERROR(__xludf.DUMMYFUNCTION("""COMPUTED_VALUE"""),"08994700800") -> 08994700800 | E8: =IFERROR(__xludf.DUMMYFUNCTION("""COMPUTED_VALUE"""),"Website") -> Website | F8: =IFERROR(__xludf.DUMMYFUNCTION("""COMPUTED_VALUE"""),"Gagal") -> Gagal | G8: =IFERROR(__xludf.DUMMYFUNCTION("""COMPUTED_VALUE"""),"3H2M A") -> 3H2M A | I8: =IFERROR(__xludf.DUMMYFUNCTION("""COMPUTED_VALUE"""),10.0) -> 10 | K8: =IFERROR(__xludf.DUMMYFUNCTION("""COMPUTED_VALUE"""),"tanya tanya, masih blm jawab follow up") -> tanya tanya, masih blm jawab follow up
A9: =IFERROR(__xludf.DUMMYFUNCTION("""COMPUTED_VALUE"""),46029.0) -> 46029 | B9: =IFERROR(__xludf.DUMMYFUNCTION("""COMPUTED_VALUE"""),"2601A008") -> 2601A008 | C9: =IFERROR(__xludf.DUMMYFUNCTION("""COMPUTED_VALUE"""),"Helmi") -> Helmi | D9: =IFERROR(__xludf.DUMMYFUNCTION("""COMPUTED_VALUE"""),"083826179860‬") -> 083826179860‬ | E9: =IFERROR(__xludf.DUMMYFUNCTION("""COMPUTED_VALUE"""),"Website") -> Website | F9: =IFERROR(__xludf.DUMMYFUNCTION("""COMPUTED_VALUE"""),"Gagal") -> Gagal | G9: =IFERROR(__xludf.DUMMYFUNCTION("""COMPUTED_VALUE"""),"1D IB") -> 1D IB | H9: =IFERROR(__xludf.DUMMYFUNCTION("""COMPUTED_VALUE"""),46030.0) -> 46030 | I9: =IFERROR(__xludf.DUMMYFUNCTION("""COMPUTED_VALUE"""),3.0) -> 3 | J9: =IFERROR(__xludf.DUMMYFUNCTION("""COMPUTED_VALUE"""),2076000.0) -> 2076000 | K9: =IFERROR(__xludf.DUMMYFUNCTION("""COMPUTED_VALUE"""),"order") -> order
A10: =IFERROR(__xludf.DUMMYFUNCTION("""COMPUTED_VALUE"""),46030.0) -> 46030 | B10: =IFERROR(__xludf.DUMMYFUNCTION("""COMPUTED_VALUE"""),"2601A009") -> 2601A009 | C10: =IFERROR(__xludf.DUMMYFUNCTION("""COMPUTED_VALUE"""),"Ruly") -> Ruly | D10: =IFERROR(__xludf.DUMMYFUNCTION("""COMPUTED_VALUE"""),"08170934898") -> 08170934898 | E10: =IFERROR(__xludf.DUMMYFUNCTION("""COMPUTED_VALUE"""),"Website") -> Website | F10: =IFERROR(__xludf.DUMMYFUNCTION("""COMPUTED_VALUE"""),"Gagal") -> Gagal | G10: =IFERROR(__xludf.DUMMYFUNCTION("""COMPUTED_VALUE"""),"3H2M A") -> 3H2M A | I10: =IFERROR(__xludf.DUMMYFUNCTION("""COMPUTED_VALUE"""),2.0) -> 2 | K10: =IFERROR(__xludf.DUMMYFUNCTION("""COMPUTED_VALUE"""),"Tidak jawab") -> Tidak jawab
A11: =IFERROR(__xludf.DUMMYFUNCTION("""COMPUTED_VALUE"""),46030.0) -> 46030 | B11: =IFERROR(__xludf.DUMMYFUNCTION("""COMPUTED_VALUE"""),"2601A010") -> 2601A010 | C11: =IFERROR(__xludf.DUMMYFUNCTION("""COMPUTED_VALUE"""),"Stephan") -> Stephan | D11: =IFERROR(__xludf.DUMMYFUNCTION("""COMPUTED_VALUE"""),"085105912829") -> 085105912829 | E11: =IFERROR(__xludf.DUMMYFUNCTION("""COMPUTED_VALUE"""),"Website") -> Website | F11: =IFERROR(__xludf.DUMMYFUNCTION("""COMPUTED_VALUE"""),"Gagal") -> Gagal | G11: =IFERROR(__xludf.DUMMYFUNCTION("""COMPUTED_VALUE"""),"4H3M") -> 4H3M | I11: =IFERROR(__xludf.DUMMYFUNCTION("""COMPUTED_VALUE"""),2.0) -> 2 | K11: =IFERROR(__xludf.DUMMYFUNCTION("""COMPUTED_VALUE"""),"lagi pikir-pikir, FU pertengahan januari") -> lagi pikir-pikir, FU pertengahan januari
A12: =IFERROR(__xludf.DUMMYFUNCTION("""COMPUTED_VALUE"""),46031.0) -> 46031 | B12: =IFERROR(__xludf.DUMMYFUNCTION("""COMPUTED_VALUE"""),"2601A011") -> 2601A011 | C12: =IFERROR(__xludf.DUMMYFUNCTION("""COMPUTED_VALUE"""),"carone") -> carone | D12: =IFERROR(__xludf.DUMMYFUNCTION("""COMPUTED_VALUE"""),"0877933043674") -> 0877933043674 | E12: =IFERROR(__xludf.DUMMYFUNCTION("""COMPUTED_VALUE"""),"Lainnya") -> Lainnya | F12: =IFERROR(__xludf.DUMMYFUNCTION("""COMPUTED_VALUE"""),"Gagal") -> Gagal | G12: =IFERROR(__xludf.DUMMYFUNCTION("""COMPUTED_VALUE"""),"3H2M") -> 3H2M | K12: =IFERROR(__xludf.DUMMYFUNCTION("""COMPUTED_VALUE"""),"Masih tanya tanya") -> Masih tanya tanya
A13: =IFERROR(__xludf.DUMMYFUNCTION("""COMPUTED_VALUE"""),46031.0) -> 46031 | B13: =IFERROR(__xludf.DUMMYFUNCTION("""COMPUTED_VALUE"""),"2601A012") -> 2601A012 | C13: =IFERROR(__xludf.DUMMYFUNCTION("""COMPUTED_VALUE"""),"Giet") -> Giet | D13: =IFERROR(__xludf.DUMMYFUNCTION("""COMPUTED_VALUE"""),"085377504433") -> 085377504433 | E13: =IFERROR(__xludf.DUMMYFUNCTION("""COMPUTED_VALUE"""),"Website") -> Website | F13: =IFERROR(__xludf.DUMMYFUNCTION("""COMPUTED_VALUE"""),"Gagal") -> Gagal | G13: =IFERROR(__xludf.DUMMYFUNCTION("""COMPUTED_VALUE"""),"3H2M") -> 3H2M | K13: =IFERROR(__xludf.DUMMYFUNCTION("""COMPUTED_VALUE"""),"masih tanya tanya") -> masih tanya tanya
A14: =IFERROR(__xludf.DUMMYFUNCTION("""COMPUTED_VALUE"""),46032.0) -> 46032 | B14: =IFERROR(__xludf.DUMMYFUNCTION("""COMPUTED_VALUE"""),"2601A013") -> 2601A013 | C14: =IFERROR(__xludf.DUMMYFUNCTION("""COMPUTED_VALUE"""),"Deni Sultan") -> Deni Sultan | D14: =IFERROR(__xludf.DUMMYFUNCTION("""COMPUTED_VALUE"""),"081912435459‬") -> 081912435459‬ | E14: =IFERROR(__xludf.DUMMYFUNCTION("""COMPUTED_VALUE"""),"Website") -> Website | F14: =IFERROR(__xludf.DUMMYFUNCTION("""COMPUTED_VALUE"""),"Closing") -> Closing | G14: =IFERROR(__xludf.DUMMYFUNCTION("""COMPUTED_VALUE"""),"MT") -> MT | H14: =IFERROR(__xludf.DUMMYFUNCTION("""COMPUTED_VALUE"""),46046.0) -> 46046 | I14: =IFERROR(__xludf.DUMMYFUNCTION("""COMPUTED_VALUE"""),2.0) -> 2 | J14: =IFERROR(__xludf.DUMMYFUNCTION("""COMPUTED_VALUE"""),590000.0) -> 590000 | K14: =IFERROR(__xludf.DUMMYFUNCTION("""COMPUTED_VALUE"""),"order") -> order
A15: =IFERROR(__xludf.DUMMYFUNCTION("""COMPUTED_VALUE"""),46031.0) -> 46031 | B15: =IFERROR(__xludf.DUMMYFUNCTION("""COMPUTED_VALUE"""),"2601A014") -> 2601A014 | C15: =IFERROR(__xludf.DUMMYFUNCTION("""COMPUTED_VALUE"""),"Asep") -> Asep | D15: =IFERROR(__xludf.DUMMYFUNCTION("""COMPUTED_VALUE"""),"085524416539") -> 085524416539 | E15: =IFERROR(__xludf.DUMMYFUNCTION("""COMPUTED_VALUE"""),"Website") -> Website | F15: =IFERROR(__xludf.DUMMYFUNCTION("""COMPUTED_VALUE"""),"Gagal") -> Gagal | G15: =IFERROR(__xludf.DUMMYFUNCTION("""COMPUTED_VALUE"""),"Trip Alas Purwo") -> Trip Alas Purwo | I15: =IFERROR(__xludf.DUMMYFUNCTION("""COMPUTED_VALUE"""),10.0) -> 10 | K15: =IFERROR(__xludf.DUMMYFUNCTION("""COMPUTED_VALUE"""),"tanya tanya") -> tanya tanya
A16: =IFERROR(__xludf.DUMMYFUNCTION("""COMPUTED_VALUE"""),46033.0) -> 46033 | B16: =IFERROR(__xludf.DUMMYFUNCTION("""COMPUTED_VALUE"""),"2601A015") -> 2601A015 | C16: =IFERROR(__xludf.DUMMYFUNCTION("""COMPUTED_VALUE"""),"Istinah") -> Istinah | D16: =IFERROR(__xludf.DUMMYFUNCTION("""COMPUTED_VALUE"""),"081334625968") -> 081334625968 | E16: =IFERROR(__xludf.DUMMYFUNCTION("""COMPUTED_VALUE"""),"Website") -> Website | F16: =IFERROR(__xludf.DUMMYFUNCTION("""COMPUTED_VALUE"""),"Gagal") -> Gagal | G16: =IFERROR(__xludf.DUMMYFUNCTION("""COMPUTED_VALUE"""),"Trip Djawatan Baluran") -> Trip Djawatan Baluran | I16: =IFERROR(__xludf.DUMMYFUNCTION("""COMPUTED_VALUE"""),10.0) -> 10 | K16: =IFERROR(__xludf.DUMMYFUNCTION("""COMPUTED_VALUE"""),"masih cari informasi") -> masih cari informasi
A17: =IFERROR(__xludf.DUMMYFUNCTION("""COMPUTED_VALUE"""),46033.0) -> 46033 | B17: =IFERROR(__xludf.DUMMYFUNCTION("""COMPUTED_VALUE"""),"2601A016") -> 2601A016 | C17: =IFERROR(__xludf.DUMMYFUNCTION("""COMPUTED_VALUE"""),"Edwin") -> Edwin | D17: =IFERROR(__xludf.DUMMYFUNCTION("""COMPUTED_VALUE"""),"085659981058") -> 085659981058 | E17: =IFERROR(__xludf.DUMMYFUNCTION("""COMPUTED_VALUE"""),"Website") -> Website | F17: =IFERROR(__xludf.DUMMYFUNCTION("""COMPUTED_VALUE"""),"Closing") -> Closing | G17: =IFERROR(__xludf.DUMMYFUNCTION("""COMPUTED_VALUE"""),"Private trip 3H2M") -> Private trip 3H2M | I17: =IFERROR(__xludf.DUMMYFUNCTION("""COMPUTED_VALUE"""),2.0) -> 2 | J17: =IFERROR(__xludf.DUMMYFUNCTION("""COMPUTED_VALUE"""),6794000.0) -> 6794000 | K17: =IFERROR(__xludf.DUMMYFUNCTION("""COMPUTED_VALUE"""),"order") -> order
A18: =IFERROR(__xludf.DUMMYFUNCTION("""COMPUTED_VALUE"""),46035.0) -> 46035 | B18: =IFERROR(__xludf.DUMMYFUNCTION("""COMPUTED_VALUE"""),"2601A017") -> 2601A017 | C18: =IFERROR(__xludf.DUMMYFUNCTION("""COMPUTED_VALUE"""),"Jessica") -> Jessica | D18: =IFERROR(__xludf.DUMMYFUNCTION("""COMPUTED_VALUE"""),"08113166995") -> 08113166995 | E18: =IFERROR(__xludf.DUMMYFUNCTION("""COMPUTED_VALUE"""),"Website") -> Website | F18: =IFERROR(__xludf.DUMMYFUNCTION("""COMPUTED_VALUE"""),"Gagal") -> Gagal | G18: =IFERROR(__xludf.DUMMYFUNCTION("""COMPUTED_VALUE"""),"Trip Ijen") -> Trip Ijen | K18: =IFERROR(__xludf.DUMMYFUNCTION("""COMPUTED_VALUE"""),"tidak ada respon") -> tidak ada respon
A19: =IFERROR(__xludf.DUMMYFUNCTION("""COMPUTED_VALUE"""),46036.0) -> 46036 | B19: =IFERROR(__xludf.DUMMYFUNCTION("""COMPUTED_VALUE"""),"2601A018") -> 2601A018 | C19: =IFERROR(__xludf.DUMMYFUNCTION("""COMPUTED_VALUE"""),"Kambali khan") -> Kambali khan | D19: =IFERROR(__xludf.DUMMYFUNCTION("""COMPUTED_VALUE"""),"081133300048") -> 081133300048 | E19: =IFERROR(__xludf.DUMMYFUNCTION("""COMPUTED_VALUE"""),"Website") -> Website | F19: =IFERROR(__xludf.DUMMYFUNCTION("""COMPUTED_VALUE"""),"Gagal") -> Gagal | G19: =IFERROR(__xludf.DUMMYFUNCTION("""COMPUTED_VALUE"""),"rekom 2H1M") -> rekom 2H1M | I19: =IFERROR(__xludf.DUMMYFUNCTION("""COMPUTED_VALUE"""),7.0) -> 7 | K19: =IFERROR(__xludf.DUMMYFUNCTION("""COMPUTED_VALUE"""),"tanya paket open trip ") -> tanya paket open trip
A20: =IFERROR(__xludf.DUMMYFUNCTION("""COMPUTED_VALUE"""),46036.0) -> 46036 | B20: =IFERROR(__xludf.DUMMYFUNCTION("""COMPUTED_VALUE"""),"2601A019") -> 2601A019 | C20: =IFERROR(__xludf.DUMMYFUNCTION("""COMPUTED_VALUE"""),"Harun") -> Harun | D20: =IFERROR(__xludf.DUMMYFUNCTION("""COMPUTED_VALUE"""),"085190940022") -> 085190940022 | E20: =IFERROR(__xludf.DUMMYFUNCTION("""COMPUTED_VALUE"""),"Website") -> Website | F20: =IFERROR(__xludf.DUMMYFUNCTION("""COMPUTED_VALUE"""),"Gagal") -> Gagal | K20: =IFERROR(__xludf.DUMMYFUNCTION("""COMPUTED_VALUE"""),"tidak ada respon") -> tidak ada respon
A21: =IFERROR(__xludf.DUMMYFUNCTION("""COMPUTED_VALUE"""),46037.0) -> 46037 | B21: =IFERROR(__xludf.DUMMYFUNCTION("""COMPUTED_VALUE"""),"2601A020") -> 2601A020 | C21: =IFERROR(__xludf.DUMMYFUNCTION("""COMPUTED_VALUE"""),"Darius") -> Darius | D21: =IFERROR(__xludf.DUMMYFUNCTION("""COMPUTED_VALUE"""),"0811508236") -> 0811508236 | E21: =IFERROR(__xludf.DUMMYFUNCTION("""COMPUTED_VALUE"""),"Website") -> Website | F21: =IFERROR(__xludf.DUMMYFUNCTION("""COMPUTED_VALUE"""),"Gagal") -> Gagal | G21: =IFERROR(__xludf.DUMMYFUNCTION("""COMPUTED_VALUE"""),"4H3M") -> 4H3M | I21: =IFERROR(__xludf.DUMMYFUNCTION("""COMPUTED_VALUE"""),10.0) -> 10 | K21: =IFERROR(__xludf.DUMMYFUNCTION("""COMPUTED_VALUE"""),"jadinya ke bali, temannya Aji") -> jadinya ke bali, temannya Aji
A22: =IFERROR(__xludf.DUMMYFUNCTION("""COMPUTED_VALUE"""),46038.0) -> 46038 | B22: =IFERROR(__xludf.DUMMYFUNCTION("""COMPUTED_VALUE"""),"2601A021") -> 2601A021 | C22: =IFERROR(__xludf.DUMMYFUNCTION("""COMPUTED_VALUE"""),"Novita ") -> Novita | D22: =IFERROR(__xludf.DUMMYFUNCTION("""COMPUTED_VALUE"""),"085600920652") -> 085600920652 | E22: =IFERROR(__xludf.DUMMYFUNCTION("""COMPUTED_VALUE"""),"Website") -> Website | F22: =IFERROR(__xludf.DUMMYFUNCTION("""COMPUTED_VALUE"""),"Gagal") -> Gagal | G22: =IFERROR(__xludf.DUMMYFUNCTION("""COMPUTED_VALUE"""),"Trip D, B") -> Trip D, B | H22: =IFERROR(__xludf.DUMMYFUNCTION("""COMPUTED_VALUE"""),46046.0) -> 46046 | K22: =IFERROR(__xludf.DUMMYFUNCTION("""COMPUTED_VALUE"""),"masih belum minat") -> masih belum minat
A23: =IFERROR(__xludf.DUMMYFUNCTION("""COMPUTED_VALUE"""),46039.0) -> 46039 | B23: =IFERROR(__xludf.DUMMYFUNCTION("""COMPUTED_VALUE"""),"2601A022") -> 2601A022 | C23: =IFERROR(__xludf.DUMMYFUNCTION("""COMPUTED_VALUE"""),"Abi Yuma") -> Abi Yuma | D23: =IFERROR(__xludf.DUMMYFUNCTION("""COMPUTED_VALUE"""),"08119025858") -> 08119025858 | E23: =IFERROR(__xludf.DUMMYFUNCTION("""COMPUTED_VALUE"""),"Website") -> Website | F23: =IFERROR(__xludf.DUMMYFUNCTION("""COMPUTED_VALUE"""),"Gagal") -> Gagal | G23: =IFERROR(__xludf.DUMMYFUNCTION("""COMPUTED_VALUE"""),"2H3M") -> 2H3M | K23: =IFERROR(__xludf.DUMMYFUNCTION("""COMPUTED_VALUE"""),"tidak jawab") -> tidak jawab
A24: =IFERROR(__xludf.DUMMYFUNCTION("""COMPUTED_VALUE"""),46039.0) -> 46039 | B24: =IFERROR(__xludf.DUMMYFUNCTION("""COMPUTED_VALUE"""),"2601A023") -> 2601A023 | C24: =IFERROR(__xludf.DUMMYFUNCTION("""COMPUTED_VALUE"""),"Aji") -> Aji | D24: =IFERROR(__xludf.DUMMYFUNCTION("""COMPUTED_VALUE"""),"082211224004") -> 082211224004 | E24: =IFERROR(__xludf.DUMMYFUNCTION("""COMPUTED_VALUE"""),"Lainnya") -> Lainnya | F24: =IFERROR(__xludf.DUMMYFUNCTION("""COMPUTED_VALUE"""),"Gagal") -> Gagal | G24: =IFERROR(__xludf.DUMMYFUNCTION("""COMPUTED_VALUE"""),"3H4M") -> 3H4M | K24: =IFERROR(__xludf.DUMMYFUNCTION("""COMPUTED_VALUE"""),"jadinya ke bali") -> jadinya ke bali
